[2024-10-11T11:14:07.957+0000] {taskinstance.py:1956} INFO - Dependencies all met for dep_context=non-requeueable deps ti=<TaskInstance: ETL.transform_and_load scheduled__2024-10-11T06:00:00+00:00 [queued]>
[2024-10-11T11:14:07.966+0000] {taskinstance.py:1956} INFO - Dependencies all met for dep_context=requeueable deps ti=<TaskInstance: ETL.transform_and_load scheduled__2024-10-11T06:00:00+00:00 [queued]>
[2024-10-11T11:14:07.967+0000] {taskinstance.py:2170} INFO - Starting attempt 2 of 2
[2024-10-11T11:14:07.981+0000] {taskinstance.py:2191} INFO - Executing <Task(PythonOperator): transform_and_load> on 2024-10-11 06:00:00+00:00
[2024-10-11T11:14:07.990+0000] {standard_task_runner.py:60} INFO - Started process 2856 to run task
[2024-10-11T11:14:07.996+0000] {standard_task_runner.py:87} INFO - Running: ['***', 'tasks', 'run', 'ETL', 'transform_and_load', 'scheduled__2024-10-11T06:00:00+00:00', '--job-id', '10', '--raw', '--subdir', 'DAGS_FOLDER/ETL.py', '--cfg-path', '/tmp/tmph6_dus36']
[2024-10-11T11:14:08.001+0000] {standard_task_runner.py:88} INFO - Job 10: Subtask transform_and_load
[2024-10-11T11:14:08.054+0000] {task_command.py:423} INFO - Running <TaskInstance: ETL.transform_and_load scheduled__2024-10-11T06:00:00+00:00 [running]> on host 39fda6c6f77a
[2024-10-11T11:14:08.127+0000] {taskinstance.py:2480} INFO - Exporting env vars: AIRFLOW_CTX_DAG_OWNER='***' AIRFLOW_CTX_DAG_ID='ETL' AIRFLOW_CTX_TASK_ID='transform_and_load' AIRFLOW_CTX_EXECUTION_DATE='2024-10-11T06:00:00+00:00' AIRFLOW_CTX_TRY_NUMBER='2' AIRFLOW_CTX_DAG_RUN_ID='scheduled__2024-10-11T06:00:00+00:00'
[2024-10-11T11:14:09.351+0000] {taskinstance.py:2698} ERROR - Task failed with exception
Traceback (most recent call last):
  File "/home/airflow/.local/lib/python3.8/site-packages/airflow/models/taskinstance.py", line 433, in _execute_task
    result = execute_callable(context=context, **execute_callable_kwargs)
  File "/home/airflow/.local/lib/python3.8/site-packages/airflow/operators/python.py", line 199, in execute
    return_value = self.execute_callable()
  File "/home/airflow/.local/lib/python3.8/site-packages/airflow/operators/python.py", line 216, in execute_callable
    return self.python_callable(*self.op_args, **self.op_kwargs)
  File "/opt/airflow/dags/ETL.py", line 128, in tranform_load
    conn = psycopg2.connect(
  File "/home/airflow/.local/lib/python3.8/site-packages/psycopg2/__init__.py", line 122, in connect
    conn = _connect(dsn, connection_factory=connection_factory, **kwasync)
psycopg2.OperationalError: connection to server at "localhost" (::1), port 5433 failed: Connection refused
	Is the server running on that host and accepting TCP/IP connections?
connection to server at "localhost" (127.0.0.1), port 5433 failed: Connection refused
	Is the server running on that host and accepting TCP/IP connections?

[2024-10-11T11:14:09.360+0000] {taskinstance.py:1138} INFO - Marking task as FAILED. dag_id=ETL, task_id=transform_and_load, execution_date=20241011T060000, start_date=20241011T111407, end_date=20241011T111409
[2024-10-11T11:14:09.372+0000] {standard_task_runner.py:107} ERROR - Failed to execute job 10 for task transform_and_load (connection to server at "localhost" (::1), port 5433 failed: Connection refused
	Is the server running on that host and accepting TCP/IP connections?
connection to server at "localhost" (127.0.0.1), port 5433 failed: Connection refused
	Is the server running on that host and accepting TCP/IP connections?
; 2856)
[2024-10-11T11:14:09.414+0000] {local_task_job_runner.py:234} INFO - Task exited with return code 1
[2024-10-11T11:14:09.437+0000] {taskinstance.py:3280} INFO - 0 downstream tasks scheduled from follow-on schedule check
